dill==0.3.5.1
ibm_db==3.1.3   #  3.02 results in "error in ibm_db setup command: use_2to3 is invalid."
ibm_db_sa==0.3.8
ibm-watson-machine-learning==1.0.333
lxml==4.9.1
lightgbm==3.3.5
nose2==0.6.0
numba==0.58.1
numpy==1.26.2
pandas==1.5.3
psycopg2-binary==2.9.5
pyarrow==11.0.0
pyod==1.0.9
requests==2.28.1
ruptures==1.1.8
scikit-learn==1.3.2
scikit-image==0.22.0
scipy==1.11.3
sqlalchemy==1.4.39
statsmodels==0.14.0
stumpy==1.12.0
tabulate==0.8.10
torch==2.1.0
urllib3==1.26.11

#
# Issue in KITT library requires package protobuf to be fixed at version 3.20.1
# Descritption:
#TypeError: Descriptors cannot not be created directly.
# If this call came from a _pb2.py file, your generated code is out of date and must be regenerated with protoc >= 3.19.0.
# If you cannot immediately regenerate your protos, some other possible workarounds are:
#  1. Downgrade the protobuf package to 3.20.x or lower.
#  2. Set PROTOCOL_BUFFERS_PYTHON_IMPLEMENTATION=python (but this will use pure-Python parsing and will be much slower).
#
#protobuf==3.20.2    # (> CP4D 4.6.3 which has 3.19.1, Version defined by JÃ¶rn/KITT 2022-Aug-11)
